Workbook
Name \a: #REF!
Name \a: #REF!
Name \a: #REF!
Name \a: #REF!
Name \a: #REF!
Name \a: #REF!
Name \a: #REF!
Name \a: #REF!
Name \a: #REF!
Name \a: #REF!
Name \a: #REF!
Name \a: #REF!
Name \a: #REF!
Name \a: #REF!
Name \a: #REF!
Name \a: #REF!
Name \a: #REF!
Name \a: #REF!
Name \a: #REF!
Name \a: #REF!
Name \a: #REF!
Name \a: #REF!
Name \a: #REF!
Name \a: #REF!
Name \a: #REF!
Name \a: #REF!
Name \a: #REF!
Name \a: #REF!
Name \a: #REF!
Name \a: #REF!
Name \a: #REF!
Name \a: #REF!
Name \a: #REF!
Name \a: #REF!
Name \a: #REF!
Name \a: #REF!
Name \a: #REF!
Name \a: #REF!
Name \a: #REF!
Name \a: #REF!
Name \a: #REF!
Name \a: #REF!
Name \a: #REF!
Name \a: #REF!
Name \a: #REF!
Name \a: #REF!
Name \a: #REF!
Name \a: #REF!
Name \a: #REF!
Name \a: #REF!
Name \a: #REF!
Name \a: #REF!
Name \a: #REF!
Name \a: #REF!
Name \a: #REF!
Name \a: #REF!
Name \a: #REF!
Name \a: #REF!
Name \a: #REF!
Name \a: #REF!

Sheet 封面-全星科技
F18: 浙江全星科技新材料股份有限公司
D26: 产品质量先期策划（APQP）
D37: 项目名称： | K37: 通用材料用工业长丝-大块金事业部PH25657
D38: Project Name: | K38: Nylon 66 tire cord fabric industrial yarn-Tire cord fabric Department PH25657
D40: 项目周期： Project Cycle | K40: 2023/8-2025.8

Sheet 目录
B1: 密级：秘密★★，未经允许不可查看；保存期限：长期
A2: 产品质量先期策划（APQP）项目资料
A3: 目 录
A4: 序号 | B4: 文件/记录名称 | C4: 全星根据体系老师建议调整 （调整的做链接可点开） | D4: 全星科技确认后记录 | E4: 文件/记录编号 | F4: 备注 | G4: 日期
A5: 第零阶段：项目启动阶段
A6: 0.01 | B6: 新产品制造可行性分析报告 | C6: 1增加设备能力（生产线实际能力） | D6: B列链接是全星科技最新版 | E6: HLD/CF-04-041-003 | G6: 2023年8月14日 | H6: 45152
A7: 0.02 | B7: 新产品开发申请/立项报告 | C7: 表单可行 | E7: HLD/CF-04-041-005 | G7: 2023年8月15日 | H7: 45153
A8: 0.03 | B8: 新产品开发小组成员及职责表 | C8: 增加了客户、供应商信息，选填 | D8: 化纤不加客户 供应商，还是按照客户原版 | E8: HLD/CF-04-041-006 | G8: 2023年8月15日 | H8: 45153
A9: 0.04 | B9: 新产品APQP开发计划 | C9: 表单可行 | E9: HLD/CF-04-041-007 | G9: 2023年8月15日 | H9: 45153
A10: 0.05 | B10: 设计评审/验证/确认记录（设计开发输入） | C10: 评审项目改成了评审阶段，点链接查看修改版 | D10: OK，按照修改版 | E10: HLD/CF-04-041-008 | G10: 2023年8月16日 | H10: 45154
A11: 第一阶段：策划和定义项目
A12: 1.01 | B12: 设计开发任务书 | C12: 表单可行 | E12: HLD/CF-04-041-009 | G12: 2023年8月17日 | H12: 45155
A13: 1.02 | B13: 初始材料清单（BOM） | C13: 表单可行 | E13: HLD/CF-04-041-011 | G13: 2023年8月18日 | H13: 45156
A14: 1.03 | B14: 成本核算及报价表 | C14: 表单可行，内容加了水电 | E14: HLD/CF-04-041-004 | G14: 2023年8月18日 | H14: 45156
A15: 1.04 | B15: 过程流程图（初始） | C15: 表单可行 | E15: HLD/CF-03-041-*** | F15: 文件 | G15: 2023年8月19日 | H15: 45157
A16: 1.05 | B16: 特殊特性符合转化表 | C16: 表单可行 | E16: HLD/CF-04-041-025 | G16: 2023年8月20日 | H16: 45158
A17: 1.06 | B17: 产品/过程特殊特性清单（初始） | C17: 表单可行 | E17: HLD/CF-04-041-012 | G17: 2023年8月20日 | H17: 45158
A18: 1.07 | B18: 产品安全识别表 | C18: 表单可行，内容增加了有害物质 | E18: HLD/CF-04-041-047 | G18: 2023年8月21日 | H18: 45159
A19: 1.08 | B19: 产品保证计划 | C19: 表单可行，包装要求中的控制方法写管控要求 | E19: HLD/CF-04-041-010 | G19: 2023年8月21日 | H19: 45159
A20: 1.09 | B20: 项目变更登记表 | C20: 表单可行 | E20: HLD/CF-04-041-048 | G20: 2023年8月21日 | H20: 45159
A21: 1.10 | B21: 风险评估和缓解计划 | C21: 表单可行 | E21: HLD/CF-04-041-049 | G21: 2023年8月21日 | H21: 45159
A22: 1.11 | B22: 设计评审/验证/确认记录（产品设计输入） | C22: 同0.05 | E22: HLD/CF-04-041-008 | G22: 2023年8月22日 | H22: 45160
A23: 1.12 | B23: 阶段性总结和管理者支持（第一阶段） | C23: 增加了问题清单 | D23: 替换二大项，确保内容项不要缺失 ，问题清单不打印，但系统保留这个列表 | E23: HLD/CF-04-041-013 | G23: 2023年8月22日 | H23: 45160
A24: 第二阶段：产品设计开发
A25: 2.01 | B25: DFMEA | C25: 内容：其中关注要素原丝改成纱线，老师会议中提出失效分析需考虑元素结合，另预防措施中建议写具体方法，目前的有点笼统，这部分讨论比较多，主要针对内容，会议视频已发出，时间大概在10:30这个视频包中 | E25: HLD/CF-03-041-*** | F25: 文件 | G25: 2023年8月22日 | H25: 45160
A26: 2.02 | B26: DFMEA检查表 | C26: 表单可行 | E26: HLD/CF-04-041-035 | G26: 2023年8月22日 | H26: 45160
A27: 2.03 | B27: 产品技术规范 | C27: 表单可行 | E27: HLD/CF-04-041-014 | G27: 2023年8月23日 | H27: 45161
A28: 2.04 | B28: 设计评审/验证/确认记录（可制造性评审） | C28: 表单可行 | E28: HLD/CF-04-041-008 | G28: 2023年8月23日 | H28: 45161
A29: 2.05 | B29: 控制计划（样件） | C29: 表单可行 | E29: HLD/CF-03-041-*** | F29: 文件 | G29: 2023年8月24日 | H29: 45162
A30: 2.06 | B30: 控制计划检查表（样件） | C30: 表单可行 | E30: HLD/CF-04-041-027 | G30: 2023年8月24日 | H30: 45162
A31: 2.07 | B31: 工艺标准（样件） | C31: 表单可行 | E31: HLD/CF-04-041-*** | F31: 文件 | G31: 2023年8月25日 | H31: 45163
A32: 2.08 | B32: 生产通知单（样件） | C32: 表单可行 | E32: QR/HLD-04-03-01 | F32: 生产计划 | G32: 2023年8月26日 | H32: 45164
A33: 2.09 | B33: 设计验证报告 | C33: 表单可行 | E33: HLD/CF-04-041-050 | G33: 2023年8月28日 | H33: 45166
A34: 2.10 | B34: 设计评审/验证/确认记录（产品设计输出） | C34: 表单可行 | E34: HLD/CF-04-041-008 | G34: 2023年8月29日 | H34: 45167
A35: 2.11 | B35: 设计更改记录 | C35: 表单可行 | E35: HLD/CF-04-041-028 | G35: 2023年12月22日 | H35: 45282 | I35: 2024年6月4日 | J35: 45447
A36: 2.12 | B36: 工程规范确认表 | C36: 表单可行 | E36: HLD/CF-04-041-015 | G36: 2023年8月30日 | H36: 45168
A37: 2.13 | B37: 材料规范确认表 | C37: 表单可行 | E37: HLD/CF-04-041-016 | G37: 2023年8月31日 | H37: 45169
A38: 2.14 | B38: 设备、工装和设施清单 | C38: 表单可行 | E38: HLD/CF-04-041-017 | G38: 2023年9月1日 | H38: 45170
A39: 2.15 | B39: 量具/试验设备清单 | C39: 修改版增加一列精度/规格是否满足 | D39: OK，按照修改版 | E39: HLD/CF-04-041-051 | G39: 2023年9月1日 | H39: 45170
A40: 2.16 | B40: 产品/过程特殊特性清单（产品设计后更新） | C40: 表单可行 | E40: HLD/CF-04-041-012 | F40: 如有变化需更新 | G40: 2023年9月2日 | H40: 45171
...

Sheet 0.01
E1: 密级：秘密★★，未经允许不可查看；保存期限：长期
A2: 新产品制造可行性分析报告 New product manufacturing feasibility analysis report
H3: 序号NO.： | K3: 0.01
A4: 新产品名称 The name of the new product | C4: 大块金用工业长丝-帘子布事业部PH25657 Nylon 66 tire cord fabric industrial yarn-Tire cord fabric Department PH25657 | F4: 新产品批号和规格Batch number and specification of new products | H4: PH25657-2800dtex/432f
F5: 顾 客 名 称 The customer name | H5: 帘子布事业部
A6: 评估部门The department responsible for evaluation | C6: 销售部/技术部 | F6: 评估日期 Date of assessment | H6: =目录!G6 -> 2023年8月14日
A7: 一、制造国，目的国，销售国的法律法规及环境方面的法律法规概述：Overview of laws and regulations of the country of manufacture, destination and seller and environmental laws and regulations:
A8: 本次开发的大块金用工业长丝制造国在中国，销售目的地为浙江海利得新材料股份有限公司帘子布事业部。 本项目开发的大块金用工业长丝产品符合GB/T 30512-2014《汽车禁用物质要求》，并已通过ROHS、REACH测试，其余法律法规的识别详见法务部《法律合规合规性评价表》。
A9: 二、顾客概况（包括：人员、工厂规模、现有主要车型、年产量、企业性质、生产经营状况、近几年发展情况等）：Customer profile (including: personnel, factory scale, existing main models, annual output, enterprise nature, production and operation status, development in recent years, etc.) :
A10: 帘子布事业部成立于2010年，2011年正式投产，员工大约650人，经营范围包括轮胎帘子布和涤纶工业长丝的设计开发，产品应用于轮胎、空气弹簧、橡胶履带、海洋软管等，纺丝产能5万吨/年，捻织7.5万吨/年，浸胶布7.2万吨/年，面积约280000㎡
A11: 三、顾客对新产品开发项目的质量和技术要求及其它基本要求（如涉及新工艺、新材料、新技术，需评估可行性）：Customer's quality and technical requirements and other basic requirements for new product development projects (if new processes, new materials and new technologies are involved, the feasibility shall be evaluated) :
A12: 按照质量和技术标准。
A13: 四、顾客对新产品的竞争选点情况（包括：有几家竞争对手与顾客配套、竞争对手的质量和技术状况、竞争对手的设计和开发能力状况等）：Customer's competitive points for new products (including: several competitors supporting customers, quality and technical status of competitors, design and development ability of competitors, etc.)
A14: 英威达/PHP神马/晓星/中维都有合作，晓星和中维为主，在PA66纱线领域都有较丰富的生产经验和开发经验
A15: 五、顾客对新产品定点及认可程序：Customer approval procedures for new products:
A16: 样品提交的认定程序如下： 1、首先进行样件或小批量的确认，具体以客户需求为准。 2、经过批量试用后开始进行批量供货。
A17: 六、市场预测：Market forecast:
A18: 预计采购量200 T/年，客户从我公司的采购量会根据我司产品研发情况再决定。
... A34: 通过以上分析，认为项目开发可行
A35: 编制/日期 Compilation/Date | F35: 审批/日期Approval/Date
A36: 表单编号： Form No : | C36: HLD/CF-04-041-003 | G36: 格式版次：第一版，第1次修改 Format edition: first edition, 1 revision

Sheet 0.01修改版
E1: 密级：秘密★★，未经允许不可查看；保存期限：长期
A2: 新产品制造可行性分析报告 New product manufacturing feasibility analysis report
A3: 序号NO.：0.01
A4: 新产品名称 The name of the new product | C4: 大块金用工业长丝-帘子布事业部PH25657 Nylon 66 tire cord fabric industrial yarn-Tire cord fabric Department PH25657 | F4: 新产品批号和规格Batch number and specification of new products | H4: PH25657-2800dtex/432f
F5: 顾 客 名 称 The customer name | H5: 帘子布事业部
A6: 评估部门 The department responsible for evaluation | C6: 技术部/销售部/生管部/供应商管理部/质量管理部/财务部/设备部 | F6: 评估日期 Date of assessment | H6: 2023年8月14日
A7: 评估项目 | D7: 分析说明 | E7: 参考附件 | F7: 可行性评估 | H7: 问题点解决对策 | J7: 负责人 | K7: 部门
F8: 可行 | G8: 不可行
A9: 1 | B9: 制造国，目的国，销售国的法律法规及环境方面的法律法规等是否识别完全 | C9: 产品是否满足环境及法律法规的要求？ | D9: 本次开发的大块金用工业长丝制造国在中国，销售目的地为浙江海利得新材料股份有限公司帘子布事业部。 本项目开发的大块金用工业长丝产品符合GB/T 30512-2014《汽车禁用物质要求》，并已通过ROHS、REACH测试，其余法律法规的识别详见法务部《法律合规合规性评价表》。 | E9: ROHS测试报告、REACH测试报告、《法律合规合规性评价表》 | K9: 技术部
C10: 产品包装是否满足环境及法律法规的要求？ | D10: 产品无出口要求，常规包装即可满足要求。
C11: 客户对安全说明的要求是否满足? | D11: 产品强力、伸长为安全特性能够满足客户要求，要求在产品标准中体现。 | E11: 《新产品开发申请/立项报告》
C12: 客户对产品使用环境的要求是否满足? | D12: 强力保持率的测试方法和要求在产品标准中体现 | E12: 《新产品开发申请/立项报告》
C13: 客户对产品使用寿命的要求是否满足? | D13: 客户无老化测试的要求，内部老化测试的测试方法和要求按照行业经验
A14: 2 | B14: 客户信息、要求是否完整 | C14: 顾客概况（包括：人员、工厂规模、现有主要车型、年产量、企业性质、生产经营状况、近几年发展情况等） | D14: 帘子布事业部成立于2010年，2011年正式投产，员工大约650人，经营范围包括轮胎帘子布和涤纶工业长丝的设计开发，产品应用于轮胎、空气弹簧、橡胶履带、海洋软管等，纺丝产能5万吨/年，捻织7.5万吨/年，浸胶布7.2万吨/年，面积约280000㎡ | K14: 销售
C15: 顾客有关部门/人员的联系电话和地址情况（包括：设计和开发部门、质量管理部门、采购部门、工程技术部门等主要负责人的联系电话和地址） | D15: 质量：万鹏辉penghui.wan@halead.com； 技术：王君毅wjy8386@halead.com
C16: 顾客对新产品开发项目的质量和技术要求及其它基本要求（如涉及新工艺、新材料、新技术，需评估可行性） | D16: 按照双方初步达成的质量标准进行设计开发；客户没有特殊要求。 | E16: 《新产品开发申请/立项报告》
A17: 3 | B17: 市场研究 | C17: 顾客对新产品的竞争选点情况（包括：有几家竞争对手与顾客配套、竞争对手的质量和技术状况、竞争对手的设计和开发能力状况等） | D17: 英威达/PHP神马/晓星/中维都有合作，晓星和中维为主，在PA66纱线领域都有较丰富的生产经验和开发经验；前期也对这些竞争对手的产品进行了测试分析，对比我司产品性能无明显差异，无风险。 | E17: 《样品检测报告》（涉密信息，不体现在APQP资料中） | K17: 销售
C18: 市场预测 | D18: 预计采购量200 T/年，客户从我公司的采购量会根据我司产品研发情况再决定。
A19: 4 | B19: 产品技术可行性分析 | C19: 技术要求（包括外观、尺寸、性能、材料要求等）是否能满足规格？ | D19: 材料为尼龙66，性能与类似产品差异不大， | K19: 技术部
C20: 如技术要求无法满足，是否得到了客户的偏差认可？ | D20: 规格可以满足要求
C21: 是否有特殊特性要求？如有，请附特殊特性清单。 | D21: 参考特殊特性清单 | E21: 特殊特性清单
C22: 是否与公司现有产品类似？如是，类似产品是？主要差异是？ | D22: 与现有开发及量产LGD车载型号类似，主要差异为BL尺寸差异（该型号为27寸大尺寸），现有开发过的最大尺寸为15.8寸 | E22: 公司现有产品类似对比
C23: 新产品先行试验和关键技术问题及风险分析（包括过去客诉、产品质量问题反馈、经验等） | D23: 1、 技术上参照现有尼龙66工业长丝生产线的工艺参数，工艺条件无风险。 2、 从客户提供的指标要求中看，生产有能力满足客户要求，风险可控。 | E23: 《经验教训总结库》
C24: 新产品开发的制造技术替代选择 | D24: 越南尼龙生产线可做F、H线的替代生产线。
A25: 5 | B25: 检测与试验能力分析 | C25: 4.1現有检测设备是否能够满足制造要求？ | D25: 可满足 | E25: MSA、《设备、工装和设施清单》 | K25: 质量管理部
C26: 4.2現有试验设备能力是否足够？ | D26: 可满足 | E26: 《量具/试验设备清单》
C27: 3.目前作业流程是否适用?作业方法作业条件是否适用? | D27: 该产品涉及的检测项目都已建立作业指导书，测试方法、条件均已与客户达成共识。 | E27: 相关检测作业指导书
A28: 6 | B28: 制造能力分析 | C28: 有特殊工艺要求/流程吗？如有，请注明 | D28: 无 | E28: 《过程流程图》 | K28: 设备部
C29: 客户指定了制造能力（CPK值，PPK值）吗？ | D29: 客户无要求时，CC/SC项按照PPK/CPK≥1.67 | E29: 《设计开发任务书》
C30: 厂内已具备该类产品之生产设备? | D30: 本产品在已有尼龙纺丝设备F、H线上生产 | E30: 《过程流程图》
A31: 7 | B31: 产能分析 | C31: 5.1生产场地和仓库场地是否足够？ | D31: 现有生产场地及仓库能够满足新产品的开发需求。 | E31: 《车间平面布置图》 | K31: 生管部
C32: 5.2人力资源是否足够？员工技能是否能够满足该产品的需求？ | D32: 每条生产线一名管线工艺员、一名质量工程师、三名操作工、三名检验人员等；员工培训后满足岗位技能要求方能上岗，每三个月会进行一次技能盘点。 | E32: 《员工技能矩阵图》
C33: 5.3产能是否能满足量产需求？ | D33: 预计2条线产能：1000T/年，剩余产量：500T/年，可以满足客户预计采购量。
A34: 8 | B34: 产品开发周期 | C34: 新产品开发的日程是否能满足？ | D34: 作为公司内部客户新项目认证的产品，计划2023年8月完成试样，试生产、批量生产需得到客户批准，具体日期待客户确定。 | E34: 《新产品APQP开发计划》 | K34: 生管部
C35: 顾客对新产品定点及认可程序 | D35: 样品提交的认定程序如下：1.首先进行样件或小批量的确认，具体以客户需求为准；2.经过批量试用后开始进行批量供货。
C36: 是否投入新的生产设备？如是，日程是否能满足？ | D36: 无 | E36: 《设备、工装和设施清单》
C37: 是否投入新的测试设备？如是，日程是否能满足？ | D37: 无 | E37: 《量具/试验设备清单》
A38: 9 | B38: 采购可行性分析 | C38: 供应商资源是否满足项目需求？ | D38: 涉及的原辅材料均已准入，无涉及新材料的开发 | E38: 《初始材料清单（BOM）》 | K38: 供应商管理部
A39: 10 | B39: 物流分析 | C39: 8.1包装规范中是否加入特殊要求(例如清洁度、渗漏、热处理、外观、防护等级、可追溯代码等)? | D39: 包装无特殊要求，目前现有包装规范能够满足要求 | E39: 《化纤事业部包装作业指导书》 | K39: 生管部
A40: 11 | B40: 财务分析 | C40: 投资预算（包括：人员投资、设施/设备投资等） | D40: 本产品在尼龙纺丝设备F、H线上生产,每条生产线一名管线工艺员、一名质量工程师、三名操作工、三名检验人员等。 | K40: 财务部
...

Sheet 0.02
E1: 密级：秘密★★，未经允许不可查看；保存期限：长期
A2: 新产品开发申请/立项报告 New product development application/project approval report
I3: 序号NO.： | J3: 0.02
A4: 新产品名称 The name of the new product | C4: ='0.01'!C4:E5 -> 大块金用工业长丝-帘子布事业部PH25657 Nylon 66 tire cord fabric industrial yarn-Tire cord fabric Department PH25657 | F4: 新产品批号和规格Batch number and specification of new products | H4: ='0.01'!H4:K4 -> PH25657-2800dtex/432f
F5: 顾 客 名 称 The customer name | H5: ='0.01'!H5:K5 -> 帘子布事业部
A6: 评估部门The department responsible for evaluation | C6: 技术部 | F6: 评估日期 Date of assessment | H6: =目录!G7 -> 2023年8月15日
A7: 新产品项目开发来源/依据Source/basis of new product project development | C7: 顾客要求/海利得尼龙66轮胎帘子布用工业长丝生产技术
A8: 新 产 品 项 目 开 发 要 求 和 / 或 顾 客 要 求 New product project development requirements and/or customer requirements
A9: 1、指标要求：
A10: NO. | B10: 项目Item | E10: 单位 Unit | G10: 开发要求standard | I10: 测试方法Method of testing
A11: 1 | B11: 线密度 Linear Density | E11: dtex | G11: 2880±30 | I11: GB/T14343
A12: 2 | B12: 线密度变异系数 CV of Linear Density | E12: % | G12: ≤1.60 | I12: GB/T14343
A13: 3 | B13: 断裂强力 Breaking Strength | E13: N | G13: ≥245.0 | I13: GB/T14344
A14: 4 | B14: 断裂强度 Tenacity | E14: cN/dtex | G14: ≥8.50 | I14: GB/T14344
A15: 5 | B15: 强度变异系数CV CV of Tenacity | E15: % | G15: ≤3.00 | I15: GB/T14344
A16: 6 | B16: 断裂伸长率 Breaking Elongation Ratio | E16: % | G16: 20.0±3.0 | I16: GB/T14344
A17: 7 | B17: 伸长变异系数CV CV of Elongation | E17: % | G17: ≤5.00 | I17: GB/T14344
A18: 8 | B18: 中间伸长4.7cN/dtex E.@4.7CN/dtex Load | E18: % | G18: 11.0±1.5 | I18: GB/T14344
A19: 9 | B19: 干热收缩率（177℃×2min×0.05cN/dtex) Shrinkage in Hot Air | E19: % | G19: 6.2±1.5 | I19: HLD method
A20: 10 | B20: 网络度（钩针法） Intermingles（Needle） | E20: nodes/m | G20: 6.0±3.0 | I20: HLD method
A21: 11 | B21: 含油率 Spin Finish Oil | E21: % | G21: 0.90±0.30 | I21: GB/T6504-NMR
A22: 12 | B22: 强力保持率（180℃×4h） Strength retention rate | E22: % | G22: ≥90 | I22: HLD method
A23: 2、产品尺寸要求：
A24: NO. | B24: 项目Item | C24: 单位 Unit | D24: 开发要求standard
A25: 1 | B25: 丝筒卷绕重量 | C25: kg | D25: 4.87±0.15
A26: 2 | B26: 丝筒卷绕米长 | C26: m | D26: Target value16500
A27: 3 | B27: 丝筒外径 | C27: mm | D27: ≤230
A28: 4 | B28: 动程 | C28: mm | D28: 252±10
A29: 5 | B29: 纸管高度 | C29: mm | D29: 300.00+0.2/-0.1
A30: 6 | B30: 纸管内径 | C30: mm | D30: 94.00+0.2/-0.1
A31: 7 | B31: 纸管外径 | C31: mm | D31: 106.00+0.2/-0.1
A32: 8 | B32: 纸管颜色 | C32: / | D32: 墨白条
A33: 3、可靠性评估参考尼龙工业长丝老化测试。
A34: 4、外观依照尼龙工业长丝外观标准。
A35: 5、双方共同试验尼龙66轮胎帘子布用工业长丝。
A36: 6、依据《新产品制造可行性分析报告》可知，该产品与涤纶高模低缩产品类似，且有尼龙工业长丝开发经验，故制造过程的风险可控。
A37: 备注Remarks
A38: 编制/日期 Compilation/Date | F38: 审批/日期Approval/Date
A39: 表单编号： Form No ： | C39: HLD/CF-04-041-005 | G39: 格式版次：第一版，第1次修改 Format edition: first edition, 1 revision

Sheet 0.02 (变更1)
E1: 密级：秘密★★，未经允许不可查看；保存期限：长期
A2: 新产品开发申请/立项报告 New product development application/project approval report
A3: 序号NO.：0.02
A4: 新产品名称 The name of the new product | C4: ='0.01'!C4:E5 -> 大块金用工业长丝-帘子布事业部PH25657 Nylon 66 tire cord fabric industrial yarn-Tire cord fabric Department PH25657 | F4: 新产品批号和规格Batch number and specification of new products | H4: ='0.01'!H4:K4 -> PH25657-2800dtex/432f
F5: 顾 客 名 称 The customer name | H5: ='0.01'!H5:K5 -> 帘子布事业部
A6: 评估部门The department responsible for evaluation | C6: 技术部 | F6: 评估日期 Date of assessment | H6: =目录!G35 -> 2023年12月22日
A7: 新产品项目开发来源/依据Source/basis of new product project development | C7: ='0.02'!C7 -> 顾客要求/海利得尼龙66轮胎帘子布用工业长丝生产技术
A8: 新 产 品 项 目 开 发 要 求 和 / 或 顾 客 要 求 New product project development requirements and/or customer requirements
A9: 1、指标要求：
A10: NO. | B10: 项目Item | E10: 单位 Unit | G10: 开发要求standard | I10: 测试方法Method of testing
A11: 1 | B11: 线密度 Linear Density | E11: dtex | G11: 2880±30 | I11: GB/T14343
A12: 2 | B12: 线密度变异系数 CV of Linear Density | E12: % | G12: ≤1.60 | I12: GB/T14343
A13: 3 | B13: 断裂强力 Breaking Strength | E13: N | G13: ≥245.0 | I13: GB/T14344
A14: 4 | B14: 断裂强度 Tenacity | E14: cN/dtex | G14: ≥8.50 | I14: GB/T14344
A15: 5 | B15: 强度变异系数CV CV of Tenacity | E15: % | G15: ≤3.00 | I15: GB/T14344
A16: 6 | B16: 断裂伸长率 Breaking Elongation Ratio | E16: % | G16: 20.0±3.0 | I16: GB/T14344
A17: 7 | B17: 伸长变异系数CV CV of Elongation | E17: % | G17: ≤5.00 | I17: GB/T14344
A18: 8 | B18: 中间伸长4.7cN/dtex E.@4.7CN/dtex Load | E18: % | G18: 11.0±1.5 | I18: GB/T14344
A19: 9 | B19: 干热收缩率（177℃×2min×0.05cN/dtex) Shrinkage in Hot Air | E19: % | G19: 6.2±1.5 | I19: HLD method
A20: 10 | B20: 网络度（钩针法） Intermingles（Needle） | E20: nodes/m | G20: 6.0±3.0 | I20: HLD method
A21: 11 | B21: 含油率 Spin Finish Oil | E21: % | G21: 0.90±0.30 | I21: GB/T6504-NMR
A22: 2、产品尺寸要求：
A23: NO. | B23: 项目Item | C23: 单位 Unit | D23: 开发要求standard
A24: 1 | B24: 丝筒卷绕重量 | C24: kg | D24: 5.34±0.15
A25: 2 | B25: 丝筒卷绕米长 | C25: m | D25: Target value18500
A26: 3 | B26: 丝筒外径 | C26: mm | D26: ≤230
A27: 4 | B27: 动程 | C27: mm | D27: 252±10
A28: 5 | B28: 纸管高度 | C28: mm | D28: 300.00+0.2/-0.1
A29: 6 | B29: 纸管内径 | C29: mm | D29: 94.00+0.2/-0.1
A30: 7 | B30: 纸管外径 | C30: mm | D30: 106.00+0.2/-0.1
A31: 8 | B31: 纸管颜色 | C31: / | D31: 墨白条
A32: 3、可靠性评估参考尼龙工业长丝老化测试。
A33: 4、外观依照尼龙工业长丝外观标准。
A34: 5、双方共同试验尼龙66轮胎帘子布用工业长丝。
A35: 6、依据《新产品制造可行性分析报告》可知，该产品与涤纶高模低缩产品类似，且有尼龙工业长丝开发经验，故制造过程的风险可控。
A36: 备注Remarks
A37: 编制/日期 Compilation/Date | F37: 审批/日期Approval/Date
A38: 表单编号：HLD/CF-04-041-005 Form No : HLD/CF-04-041-005 | H38: 格式版次：第一版，第1次修改 Format edition: first edition, 1 revision

Sheet 0.02 (变更2)
E1: 密级：秘密★★，未经允许不可查看；保存期限：长期
A2: 新产品开发申请/立项报告 New product development application/project approval report
I3: 序号NO.： | J3: 0.02
A4: 新产品名称 The name of the new product | C4: ='0.01'!C4:E5 -> 大块金用工业长丝-帘子布事业部PH25657 Nylon 66 tire cord fabric industrial yarn-Tire cord fabric Department PH25657 | F4: 新产品批号和规格Batch number and specification of new products | H4: ='0.01'!H4:K4 -> PH25657-2800dtex/432f
F5: 顾 客 名 称 The customer name | H5: ='0.01'!H5:K5 -> 帘子布事业部
A6: 评估部门The department responsible for evaluation | C6: 技术部 | F6: 评估日期 Date of assessment | H6: =目录!I35 -> 2024年6月4日
A7: 新产品项目开发来源/依据Source/basis of new product project development | C7: ='0.02'!C7 -> 顾客要求/海利得尼龙66轮胎帘子布用工业长丝生产技术
A8: 新 产 品 项 目 开 发 要 求 和 / 或 顾 客 要 求 New product project development requirements and/or customer requirements
A9: 1、指标要求：
A10: NO. | B10: 项目Item | E10: 单位 Unit | G10: 开发要求standard | I10: 测试方法Method of testing
A11: 1 | B11: 线密度 Linear Density | E11: dtex | G11: 2880±30 | I11: GB/T14343
A12: 2 | B12: 线密度变异系数 CV of Linear Density | E12: % | G12: ≤1.60 | I12: GB/T14343
A13: 3 | B13: 断裂强力 Breaking Strength | E13: N | G13: ≥245.0 | I13: GB/T14344
A14: 4 | B14: 断裂强度 Tenacity | E14: cN/dtex | G14: ≥8.50 | I14: GB/T14344
A15: 5 | B15: 强度变异系数CV CV of Tenacity | E15: % | G15: ≤3.00 | I15: GB/T14344
A16: 6 | B16: 断裂伸长率 Breaking Elongation Ratio | E16: % | G16: 20.0±3.0 | I16: GB/T14344
A17: 7 | B17: 伸长变异系数CV CV of Elongation | E17: % | G17: ≤5.00 | I17: GB/T14344
A18: 8 | B18: 中间伸长4.7cN/dtex E.@4.7CN/dtex Load | E18: % | G18: 11.0±1.5 | I18: GB/T14344
A19: 9 | B19: 干热收缩率（177℃×2min×0.05cN/dtex) Shrinkage in Hot Air | E19: % | G19: 5.2±1.5 | I19: HLD method
A20: 10 | B20: 网络度（钩针法） Intermingles（Needle） | E20: nodes/m | G20: 6.0±3.0 | I20: HLD method
A21: 11 | B21: 含油率 Spin Finish Oil | E21: % | G21: 0.90±0.30 | I21: GB/T6504-NMR
A22: 2、产品尺寸要求：
A23: NO. | B23: 项目Item | C23: 单位 Unit | D23: 开发要求standard
A24: 1 | B24: 丝筒卷绕重量 | C24: kg | D24: 5.34±0.15
A25: 2 | B25: 丝筒卷绕米长 | C25: m | D25: Target value18500
A26: 3 | B26: 丝筒外径 | C26: mm | D26: ≤230
A27: 4 | B27: 动程 | C27: mm | D27: 252±10
A28: 5 | B28: 纸管高度 | C28: mm | D28: 300.00+0.2/-0.1
A29: 6 | B29: 纸管内径 | C29: mm | D29: 94.00+0.2/-0.1
A30: 7 | B30: 纸管外径 | C30: mm | D30: 106.00+0.2/-0.1
A31: 8 | B31: 纸管颜色 | C31: / | D31: 墨白条
A32: 3、可靠性评估参考尼龙工业长丝老化测试。
A33: 4、外观依照尼龙工业长丝外观标准。
A34: 5、双方共同试验尼龙66轮胎帘子布用工业长丝。
A35: 6、依据《新产品制造可行性分析报告》可知，该产品与涤纶高模低缩产品类似，且有尼龙工业长丝开发经验，故制造过程的风险可控。
A36: 备注Remarks
A37: 编制/日期 Compilation/Date | F37: 审批/日期Approval/Date
A38: 表单编号： Form No ： | C38: HLD/CF-04-041-005 | G38: 格式版次：第一版，第1次修改 Format edition: first edition, 1 revision

Sheet 0.03
B1: 密级：秘密★★，未经允许不可查看；保存期限：长期
A2: 新产品开发小组成员及职责表 New product development team members and responsibilities
Q3: 序号NO.： | T3: 0.03
A4: 新产品名称 The name of the new product | C4: ='0.01'!C4:E5 -> 大块金用工业长丝-帘子布事业部PH25657 Nylon 66 tire cord fabric industrial yarn-Tire cord fabric Department PH25657 | I4: 新产品批号和规格 Batch number and specification of new products | L4: ='0.01'!H4 -> PH25657-2800dtex/432f
A5: 顾 客 名 称 The customer name | C5: ='0.01'!H5 -> 帘子布事业部 | I5: 成立日期 Date of Establishment | L5: =目录!G8 -> 2023年8月15日
A6: 一、事业部总经理任命APQP小组组长 The DEPUTY General Manager APQP team leader
A7: 二、多方论证小组成员 Member of the multi-argument team
A8: 序号 STT | B8: 姓 名 name | C8: 部 门 department | D8: 联系方式 Contact information | F8: 职责/工作内容 Responsibilities/Work content | M8: 工作负荷是否能满足 Whether the workload can be met | N8: 技能要求 Skill requirement
D9: 电话号码 telephone | E9: 邮箱地址 e-mail | N9: APQP | O9: CP | P9: DFMEA | Q9: PFMEA | R9: MSA | S9: SPC | T9: PPAP | U9: CAD
A10: 组长 The group leader | B10: 顾锋 | C10: 技术部 | D10: 13819374644 | E10: gufeng@halead.com | F10: 组建小组、确定小组成员每一部门代表方的角色和职责及工作，对所提出来的设计、性能要求和制造过程评定其可行性； | M10: 满足 | N10: √ | O10: √ | P10: √ | Q10: √ | S10: √ | T10: √
A11: 组员Team members | B11: 顾钰炜 | C11: 生产部 | D11: 13567303680 | E11: yuwei.gu@halead.com | F11: 负责样品的生产过程实现； | M11: 满足 | N11: √ | O11: √ | Q11: √ | S11: √
B12: 谢明智 | C12: 生产部 | D12: 15968349927 | E12: mingzhi.xie@halead.com | F12: 负责样品在试制过程中的工艺参数的调整及指标跟踪，写试样总结报告； | M12: 满足 | N12: √ | O12: √ | Q12: √ | S12: √
B13: 俞锋 | C13: 技术部 | D13: 15967393217 | E13: feng.yu@halead.com | F13: 负责样品试制的记录汇总；新物料试用评定，建立技术规范； | M13: 满足 | N13: √ | O13: √ | P13: √ | Q13: √ | S13: √ | T13: √
B14: 宋琴 | C14: 供应部 | D14: 13757338425 | E14: qin.song@halead.com | F14: 负责原辅材料采购； | M14: 满足 | N14: √ | O14: √ | T14: √
B15: 熊初珍 | C15: 供应商管理部 | D15: 13967338690 | E15: hrxcz@halead.com | F15: 负责将客户要求传达给供应商；新供应商、新物料开发； | M15: 满足 | N15: √ | O15: √ | T15: √
B16: 叶莉莎 | C16: 财务部 | D16: 15957342609 | E16: lisa@halead.com | F16: 负责财务预算； | M16: 满足 | N16: √
B17: 冯梦婷 | C17: 生管部 | D17: 13750732823 | E17: fmt@halead.com | F17: 负责安排生产计划，开发进度、交付/提交时间及其它必须考虑的限制条件； | M17: 满足 | N17: √ | O17: √
B18: 崔真真 | C18: 质量管理部 | D18: 18268406852 | E18: czz@halead.com | F18: 整个过程产品的质量管理，数据收集整理汇总,与客户质量沟通与对接； | M18: 满足 | N18: √ | O18: √ | Q18: √ | R18: √ | S18: √ | T18: √
B19: 蒋佳贤 | C19: 质量管理部 | D19: 18205839553 | E19: jiaxian.jiang@halead.com | F19: 负责样品在试制过程中的产品检测、数据收集整理； | M19: 满足 | N19: √ | O19: √ | Q19: √ | R19: √ | S19: √ | T19: √
B20: 马俞锋 | C20: 设备动力部 | D20: 13750742172 | E20: myf@halead.com | F20: 负责开发过程中相关设备方面的支持； | M20: 满足 | N20: √ | O20: √ | U20: √
B21: 谢陈龙 | C21: 设备动力部 | D21: 18258360325 | E21: chenlong.xie@halead.com | M21: 满足
B22: 朱翌熹 | C22: 销售部 | D22: 13567301718 | E22: zyx123@halead.com | F22: 负责与客户的联系、沟通、样品试制进程的反馈等。 | M22: 满足 | N22: √ | O22: √ | T22: √
A23: 三、APQP小组所有成员对产品、图样、技术文件、数据资料保密。All members of the APQP team keep confidential the products, drawings, technical documents and data.
A24: 四、当小组成员调岗、离岗或者执行任务超出权限时，由组长负责协调或者指派其他人员负责，必要时更新《小组开发成员责任表》。When team members are transferred, leave their posts, or perform tasks beyond their authority, the team leader is responsible for coordinating or appointing other personnel to be responsible, and update the "Group Development Member Responsibility Form" if necessary.
A25: 编制/日期 Compilation/Date | H25: 审批/日期Approval/Date
A26: 表单编号： Form No： | E26: HLD/CF-04-041-006 | J26: 格式版次：第一版，第2次修改 Format edition: first edition, 2 revision

Sheet 0.03修改版
B1: 密级：秘密★★，未经允许不可查看；保存期限：长期
A2: 新产品开发小组成员及职责表 New product development team members and responsibilities
Q3: 序号NO.： | T3: 0.03
A4: 新产品名称 The name of the new product | C4: ='0.01'!C4:E5 -> 大块金用工业长丝-帘子布事业部PH25657 Nylon 66 tire cord fabric industrial yarn-Tire cord fabric Department PH25657 | I4: 新产品批号和规格 Batch number and specification of new products | L4: ='0.01'!H4 -> PH25657-2800dtex/432f
A5: 顾 客 名 称 The customer name | C5: ='0.01'!H5 -> 帘子布事业部 | I5: 成立日期 Date of Establishment | L5: =目录!G8 -> 2023年8月15日
A6: 一、事业部总经理任命APQP小组组长 The DEPUTY General Manager APQP team leader
A7: 二、多方论证小组成员 Member of the multi-argument team
A8: 序号 STT | B8: 姓 名 name | C8: 部 门 department | D8: 联系方式 Contact information | F8: 职责/工作内容 Responsibilities/Work content | M8: 工作负荷是否能满足 Whether the workload can be met | N8: 技能要求 Skill requirement
D9: 电话号码 telephone | E9: 邮箱地址 e-mail | N9: APQP | O9: CP | P9: DFMEA | Q9: PFMEA | R9: MSA | S9: SPC | T9: PPAP | U9: CAD
A10: 组长 The group leader | B10: 顾锋 | C10: 技术部 | D10: 13819374644 | E10: gufeng@halead.com | F10: 组建小组、确定小组成员每一部门代表方的角色和职责及工作，对所提出来的设计、性能要求和制造过程评定其可行性； | M10: 满足 | N10: √ | O10: √ | P10: √ | Q10: √ | S10: √ | T10: √
A11: 组员Team members | B11: 顾钰炜 | C11: 生产部 | D11: 13567303680 | E11: yuwei.gu@halead.com | F11: 负责样品的生产过程实现； | M11: 满足 | N11: √ | O11: √ | Q11: √ | S11: √
B12: 谢明智 | C12: 生产部 | D12: 15968349927 | E12: mingzhi.xie@halead.com | F12: 负责样品在试制过程中的工艺参数的调整及指标跟踪，写试样总结报告； | M12: 满足 | N12: √ | O12: √ | Q12: √ | S12: √
B13: 俞锋 | C13: 技术部 | D13: 15967393217 | E13: feng.yu@halead.com | F13: 负责样品试制的记录汇总；新物料试用评定，建立技术规范； | M13: 满足 | N13: √ | O13: √ | P13: √ | Q13: √ | S13: √ | T13: √
B14: 宋琴 | C14: 供应部 | D14: 13757338425 | E14: qin.song@halead.com | F14: 负责原辅材料采购； | M14: 满足 | N14: √ | O14: √ | T14: √
B15: 熊初珍 | C15: 供应商管理部 | D15: 13967338690 | E15: hrxcz@halead.com | F15: 负责将客户要求传达给供应商；新供应商、新物料开发； | M15: 满足 | N15: √ | O15: √ | T15: √
B16: 叶莉莎 | C16: 财务部 | D16: 15957342609 | E16: lisa@halead.com | F16: 负责财务预算； | M16: 满足 | N16: √
B17: 冯梦婷 | C17: 生管部 | D17: 13750732823 | E17: fmt@halead.com | F17: 负责安排生产计划，开发进度、交付/提交时间及其它必须考虑的限制条件； | M17: 满足 | N17: √ | O17: √
B18: 崔真真 | C18: 质量管理部 | D18: 18268406852 | E18: czz@halead.com | F18: 整个过程产品的质量管理，数据收集整理汇总,与客户质量沟通与对接； | M18: 满足 | N18: √ | O18: √ | Q18: √ | R18: √ | S18: √ | T18: √
B19: 蒋佳贤 | C19: 质量管理部 | D19: 18205839553 | E19: jiaxian.jiang@halead.com | F19: 负责样品在试制过程中的产品检测、数据收集整理； | M19: 满足 | N19: √ | O19: √ | Q19: √ | R19: √ | S19: √ | T19: √
B20: 马俞锋 | C20: 设备动力部 | D20: 13750742172 | E20: myf@halead.com | F20: 负责开发过程中相关设备方面的支持； | M20: 满足 | N20: √ | O20: √ | U20: √
B21: 谢陈龙 | C21: 设备动力部 | D21: 18258360325 | E21: chenlong.xie@halead.com | M21: 满足
B22: 朱翌熹 | C22: 销售部 | D22: 13567301718 | E22: zyx123@halead.com | F22: 负责与客户的联系、沟通、样品试制进程的反馈等。 | M22: 满足 | N22: √ | O22: √ | T22: √
A23: 客户信息
A24: 序号 STT | B24: 姓 名 name | C24: 部 门 department | D24: 联系方式 Contact information | F24: 职责/工作内容 Responsibilities/Work content | M24: 工作负荷是否能满足 Whether the workload can be met | N24: 技能要求 Skill requirement
D25: 电话号码 telephone | E25: 邮箱地址 e-mail | N25: APQP | O25: CP | P25: DFMEA | Q25: PFMEA | R25: MSA | S25: SPC | T25: PPAP | U25: CAD
A27: 供应商信息
A28: 序号 STT | B28: 姓 名 name | C28: 部 门 department | D28: 联系方式 Contact information | F28: 职责/工作内容 Responsibilities/Work content | M28: 工作负荷是否能满足 Whether the workload can be met | N28: 技能要求 Skill requirement
D29: 电话号码 telephone | E29: 邮箱地址 e-mail | N29: APQP | O29: CP | P29: DFMEA | Q29: PFMEA | R29: MSA | S29: SPC | T29: PPAP | U29: CAD
A31: 三、APQP小组所有成员对产品、图样、技术文件、数据资料保密。All members of the APQP team keep confidential the products, drawings, technical documents and data.
A33: 四、当小组成员调岗、离岗或者执行任务超出权限时，由组长负责协调或者指派其他人员负责，必要时更新《小组开发成员责任表》。When team members are transferred, leave their posts, or perform tasks beyond their authority, the team leader is responsible for coordinating or appointing other personnel to be responsible, and update the "Group Development Member Responsibility Form" if necessary.
A35: 编制/日期 Compilation/Date | H35: 审批/日期Approval/Date
A36: 表单编号： Form No： | E36: HLD/CF-04-041-006 | J36: 格式版次：第一版，第2次修改 Format edition: first edition, 2 revision

Sheet 0.04
P1: 密级：秘密★★，未经允许不可查看；保存期限：长期
A2: 新产品APQP开发计划 New product APQP development plan
BT3: 序号NO.： | BV3: 0.04
A4: 新产品名称 The name of the new product | C4: ='0.01'!C4:E5 -> 大块金用工业长丝-帘子布事业部PH25657 Nylon 66 tire cord fabric industrial yarn-Tire cord fabric Department PH25657 | E4: 新产品批号和规格 Batch number and specification of new products | M4: ='0.01'!H4 -> PH25657-2800dtex/432f | AA4: 顾 客 名 称 The customer name | AL4: ='0.01'!H5 -> 帘子布事业部 | BB4: 日期 Date | BU4: 2023年8月15日
A5: 序号 STT | B5: 工作内容 Job content | D5: 责任部门The responsibility department | E5: 负责人head | F5: 计划plan | J5: 实际The actual | N5: 2023年 | V5: 2024年 | AT5: 2025年 | BU5: 签字 Signature | BV5: 状态
F6: 开始时间 The start time | H6: 结束时间 The end of time | J6: 开始时间 The start time | L6: 完成时间 Completion time | N6: W | O6: W | P6: W | Q6: W | R6: W | S6: W | T6: W | U6: W | V6: W | W6: W | X6: W | Y6: W | Z6: W | AA6: W | AB6: W | AC6: W | AD6: W | AE6: W | AF6: W | AG6: W | AH6: W | AI6: W | AJ6: W | AK6: W | AL6: W | AM6: W | AN6: W | AO6: W | AP6: W | AQ6: W | AR6: W | AS6: W | AT6: W | AU6: W | AV6: W | AW6: W | AX6: W | AY6: W | AZ6: W | BA6: W | BB6: W | BC6: W | BD6: W | BE6: W | BF6: W | BG6: W | BH6: W | BI6: W | BJ6: W | BK6: W | BL6: W | BM6: W | BN6: W | BO6: W | BP6: W | BQ6: W | BR6: W | BS6: W | BT6: W | BV6: 完成 | BW6: 执行中 | BX6: 未完成
N7: 32 | O7: 33 | P7: 34 | Q7: 35 | R7: 36 | S7: 37 | T7: 38 | U7: 51 | V7: 20 | W7: 21 | X7: 22 | Y7: 23 | Z7: 24 | AA7: 25 | AB7: 26 | AC7: 27 | AD7: 29 | AE7: 34 | AF7: 35 | AG7: 36 | AH7: 37 | AI7: 38 | AJ7: 43 | AK7: 44 | AL7: 45 | AM7: 46 | AN7: 47 | AO7: 49 | AP7: 50 | AQ7: 51 | AR7: 52 | AS7: 53 | AT7: 10 | AU7: 11 | AV7: 12 | AW7: 13 | AX7: 14 | AY7: 15 | AZ7: 16 | BA7: 17 | BB7: 18 | BC7: 19 | BD7: 20 | BE7: 21 | BF7: 22 | BG7: 23 | BH7: 24 | BI7: 25 | BJ7: 29 | BK7: 30 | BL7: 35 | BM7: 36 | BN7: 37 | BO7: 38 | BP7: 39 | BQ7: 40 | BR7: 41 | BS7: 50 | BT7: 51 | BW7: 执行中 | BX7: 未完成
A8: 0 | B8: 项目启动阶段 Project start-up phase
A9: 0.01 | B9: 新产品制造可行性分析报告 New product manufacturing feasibility analysis report | D9: 技术部 | E9: 俞锋 | F9: =WEEKNUM(G9) -> 33 | G9: 2023/8/14 | H9: =WEEKNUM(I9) -> 33 | I9: =G9+1 -> 45153 | J9: =WEEKNUM(K9) -> 33 | K9: =M9 -> 45152 | L9: =WEEKNUM(M9) -> 33 | M9: =目录!H6 -> 45152
A11: 0.02 | B11: 新产品开发申请/立项报告（内部里程碑） New product development application/project approval report(Internal milestones） | D11: 技术部 | E11: 俞锋 | F11: =WEEKNUM(G11) -> 33 | G11: 2023/8/15 | H11: =WEEKNUM(I11) -> 33 | I11: =G11+1 -> 45154 | J11: =WEEKNUM(K11) -> 33 | K11: =M11 -> 45153 | L11: =WEEKNUM(M11) -> 33 | M11: =目录!H7 -> 45153
A13: 0.03 | B13: 新产品开发小组成员及职责表 New product development team members and responsibilities | D13: 技术部 | E13: 俞锋 | F13: =WEEKNUM(G13) -> 33 | G13: 2023/8/16 | H13: =WEEKNUM(I13) -> 33 | I13: =G13+1 -> 45155 | J13: =WEEKNUM(K13) -> 33 | K13: =M13 -> 45153 | L13: =WEEKNUM(M13) -> 33 | M13: =目录!H8 -> 45153
A15: 0.04 | B15: 新产品APQP开发计划（内部里程碑） New product APQP development plan(Internal milestones） | D15: 技术部 | E15: 俞锋 | F15: =WEEKNUM(G15) -> 33 | G15: 2023/8/17 | H15: =WEEKNUM(I15) -> 33 | I15: =G15+1 -> 45156 | J15: =WEEKNUM(K15) -> 33 | K15: =M15 -> 45153 | L15: =WEEKNUM(M15) -> 33 | M15: =目录!H9 -> 45153
A17: 0.05 | B17: 设计评审/验证/确认记录（设计开发输入） Design Review/validation/validation record (Design and development input) | D17: 项目小组 | E17: 俞锋 | F17: =WEEKNUM(G17) -> 33 | G17: 2023/8/18 | H17: =WEEKNUM(I17) -> 33 | I17: =G17+1 -> 45157 | J17: =WEEKNUM(K17) -> 33 | K17: =M17 -> 45154 | L17: =WEEKNUM(M17) -> 33 | M17: =目录!H10 -> 45154
A19: 1 | B19: 策划和定义项目 Plan and identify projects
A20: 1.01 | B20: 设计开发任务书 Design and development specification | D20: 技术部 | E20: 俞锋 | F20: =WEEKNUM(G20) -> 33 | G20: 2023/8/19 | H20: =WEEKNUM(I20) -> 34 | I20: =G20+1 -> 45158 | J20: =WEEKNUM(K20) -> 33 | K20: =M20 -> 45155 | L20: =WEEKNUM(M20) -> 33 | M20: =目录!H12 -> 45155
A22: 1.02 | B22: 初始材料清单 BOM Initial material list BOM | D22: 技术部 | E22: 俞锋 | F22: =WEEKNUM(G22) -> 34 | G22: 2023/8/20 | H22: =WEEKNUM(I22) -> 34 | I22: =G22+1 -> 45159 | J22: =WEEKNUM(K22) -> 33 | K22: =M22 -> 45156 | L22: =WEEKNUM(M22) -> 33 | M22: =目录!H13 -> 45156
A24: 1.03 | B24: 成本核算及报价表 Cost accounting and quotation sheet | D24: 项目小组 | E24: 俞锋 | F24: =WEEKNUM(G24) -> 34 | G24: 2023/8/21 | H24: =WEEKNUM(I24) -> 34 | I24: =G24+1 -> 45160 | J24: =WEEKNUM(K24) -> 33 | K24: =M24 -> 45156 | L24: =WEEKNUM(M24) -> 33 | M24: =目录!H14 -> 45156
A26: 1.04 | B26: 过程流程图（初始） Process flow Chart (initial) | D26: 技术部 | E26: 俞锋 | F26: =WEEKNUM(G26) -> 34 | G26: 2023/8/22 | H26: =WEEKNUM(I26) -> 34 | I26: =G26+1 -> 45161 | J26: =WEEKNUM(K26) -> 33 | K26: =M26 -> 45157 | L26: =WEEKNUM(M26) -> 33 | M26: =目录!H15 -> 45157
A28: 1.05 | B28: 特殊特性符合转化表 The special characteristics correspond to the transformation table | D28: 技术部 | E28: 俞锋 | F28: =WEEKNUM(G28) -> 34 | G28: 2023/8/23 | H28: =WEEKNUM(I28) -> 34 | I28: =G28+1 -> 45162 | J28: =WEEKNUM(K28) -> 34 | K28: =M28 -> 45158 | L28: =WEEKNUM(M28) -> 34 | M28: =目录!H16 -> 45158
A30: 1.06 | B30: 产品/过程特殊特性清单（初始） List of product/process special features (initial) | D30: 技术部 | E30: 俞锋 | F30: =WEEKNUM(G30) -> 34 | G30: 2023/8/24 | H30: =WEEKNUM(I30) -> 34 | I30: =G30+1 -> 45163 | J30: =WEEKNUM(K30) -> 34 | K30: =M30 -> 45158 | L30: =WEEKNUM(M30) -> 34 | M30: =目录!H17 -> 45158
A32: 1.07 | B32: 产品安全识别表 Product safety identification form | D32: 技术部 | E32: 俞锋 | F32: =WEEKNUM(G32) -> 34 | G32: 2023/8/25 | H32: =WEEKNUM(I32) -> 34 | I32: =G32+1 -> 45164 | J32: =WEEKNUM(K32) -> 34 | K32: =M32 -> 45159 | L32: =WEEKNUM(M32) -> 34 | M32: =目录!H18 -> 45159
A34: 1.08 | B34: 产品保证计划 Product Assurance Program | D34: 技术部 | E34: 俞锋 | F34: =WEEKNUM(G34) -> 34 | G34: 2023/8/26 | H34: =WEEKNUM(I34) -> 35 | I34: =G34+1 -> 45165 | J34: =WEEKNUM(K34) -> 34 | K34: =M34 -> 45159 | L34: =WEEKNUM(M34) -> 34 | M34: =目录!H19 -> 45159
A36: 1.09 | B36: 项目变更登记表 Project change registration form | D36: 技术部 | E36: 俞锋 | F36: =WEEKNUM(G36) -> 35 | G36: 2023/8/27 | H36: =WEEKNUM(I36) -> 35 | I36: =G36+1 -> 45166 | J36: =WEEKNUM(K36) -> 34 | K36: =M36 -> 45159 | L36: =WEEKNUM(M36) -> 34 | M36: =目录!H20 -> 45159
A38: 1.10 | B38: 风险评估和缓解计划 Risk assessment and mitigation planning | D38: 技术部 | E38: 俞锋 | F38: =WEEKNUM(G38) -> 35 | G38: 2023/8/28 | H38: =WEEKNUM(I38) -> 35 | I38: =G38+1 -> 45167 | J38: =WEEKNUM(K38) -> 34 | K38: =M38 -> 45159 | L38: =WEEKNUM(M38) -> 34 | M38: =目录!H21 -> 45159
A40: 1.11 | B40: 设计评审/验证/确认记录（产品设计输入） Design Review/validation/validation record (Product design input) | D40: 项目小组 | E40: 俞锋 | F40: =WEEKNUM(G40) -> 35 | G40: 2023/8/29 | H40: =WEEKNUM(I40) -> 35 | I40: =G40+1 -> 45168 | J40: =WEEKNUM(K40) -> 34 | K40: =M40 -> 45160 | L40: =WEEKNUM(M40) -> 34 | M40: =目录!H22 -> 45160
A42: 1.12 | B42: 阶段性总结和管理者支持 Periodic summary and manager support | D42: 项目小组 | E42: 俞锋 | F42: =WEEKNUM(G42) -> 35 | G42: 2023/8/30 | H42: =WEEKNUM(I42) -> 35 | I42: =G42+1 -> 45169 | J42: =WEEKNUM(K42) -> 34 | K42: =M42 -> 45160 | L42: =WEEKNUM(M42) -> 34 | M42: =目录!H23 -> 45160
A44: 2 | B44: 产品设计与开发 Product design and development
A45: 2.01 | B45: DFMEA | D45: 技术部 | E45: 俞锋 | F45: =WEEKNUM(G45) -> 35 | G45: 2023/9/1 | H45: =WEEKNUM(I45) -> 35 | I45: =G45+1 -> 45171 | J45: =WEEKNUM(K45) -> 34 | K45: =M45 -> 45160 | L45: =WEEKNUM(M45) -> 34 | M45: =目录!H25 -> 45160
A47: 2.02 | B47: DFMEA检查表 Checklist for DFMEA | D47: 技术部 | E47: 俞锋 | F47: =WEEKNUM(G47) -> 35 | G47: 2023/9/2 | H47: =WEEKNUM(I47) -> 36 | I47: =G47+1 -> 45172 | J47: =WEEKNUM(K47) -> 34 | K47: =M47 -> 45160 | L47: =WEEKNUM(M47) -> 34 | M47: =目录!H26 -> 45160
A49: 2.03 | B49: 产品技术规范 Product technical specification | D49: 技术部 | E49: 俞锋 | F49: =WEEKNUM(G49) -> 36 | G49: 2023/9/3 | H49: =WEEKNUM(I49) -> 36 | I49: =G49+1 -> 45173 | J49: =WEEKNUM(K49) -> 34 | K49: =M49 -> 45161 | L49: =WEEKNUM(M49) -> 34 | M49: =目录!H27 -> 45161
A51: 2.04 | B51: 设计评审/验证/确认记录 （可制造性评审） Design Review/Validation/validation Record (Manufacturability review) | D51: 项目小组 | E51: 俞锋 | F51: =WEEKNUM(G51) -> 36 | G51: 2023/9/4 | H51: =WEEKNUM(I51) -> 36 | I51: =G51+1 -> 45174 | J51: =WEEKNUM(K51) -> 34 | K51: =M51 -> 45161 | L51: =WEEKNUM(M51) -> 34 | M51: =目录!H28 -> 45161
A53: 2.05 | B53: 控制计划（样件） Control plan (Prototype) | D53: 技术部 | E53: 俞锋 | F53: =WEEKNUM(G53) -> 36 | G53: 2023/9/5 | H53: =WEEKNUM(I53) -> 36 | I53: =G53+1 -> 45175 | J53: =WEEKNUM(K53) -> 34 | K53: =M53 -> 45162 | L53: =WEEKNUM(M53) -> 34 | M53: =目录!H29 -> 45162
A55: 2.06 | B55: 控制计划检查表 Control plan checklist | D55: 项目小组 | E55: 俞锋 | F55: =WEEKNUM(G55) -> 36 | G55: 2023/9/6 | H55: =WEEKNUM(I55) -> 36 | I55: =G55+1 -> 45176 | J55: =WEEKNUM(K55) -> 34 | K55: =M55 -> 45162 | L55: =WEEKNUM(M55) -> 34 | M55: =目录!H30 -> 45162
A57: 2.07 | B57: 工艺标准（样件） Process standard (Prototype) | D57: 技术部 | E57: 俞锋 | F57: =WEEKNUM(G57) -> 36 | G57: 2023/9/7 | H57: =WEEKNUM(I57) -> 36 | I57: =G57+1 -> 45177 | J57: =WEEKNUM(K57) -> 34 | K57: =M57 -> 45163 | L57: =WEEKNUM(M57) -> 34 | M57: =目录!H31 -> 45163
A59: 2.08 | B59: 生产通知单（样件）（内部里程碑） Production order (Prototype)(Internal milestones） | D59: 生管部 | E59: 冯梦婷 | F59: =WEEKNUM(G59) -> 36 | G59: 2023/9/8 | H59: =WEEKNUM(I59) -> 36 | I59: =G59+1 -> 45178 | J59: =WEEKNUM(K59) -> 34 | K59: =M59 -> 45164 | L59: =WEEKNUM(M59) -> 34 | M59: =目录!H32 -> 45164
A61: 2.09 | B61: 设计验证报告 Design verification report | D61: 技术部 | E61: 俞锋 | F61: =WEEKNUM(G61) -> 36 | G61: 2023/9/9 | H61: =WEEKNUM(I61) -> 37 | I61: =G61+1 -> 45179 | J61: =WEEKNUM(K61) -> 35 | K61: =M61 -> 45166 | L61: =WEEKNUM(M61) -> 35 | M61: =目录!H33 -> 45166
A63: 2.10 | B63: 设计评审验证确认记录-产品设计输出评审 Design Review Validation Record - product design output review | D63: 项目小组 | E63: 俞锋 | F63: =WEEKNUM(G63) -> 37 | G63: 2023/9/10 | H63: =WEEKNUM(I63) -> 37 | I63: =G63+1 -> 45180 | J63: =WEEKNUM(K63) -> 35 | K63: =M63 -> 45167 | L63: =WEEKNUM(M63) -> 35 | M63: =目录!H34 -> 45167
A65: 2.11 | B65: 设计更改记录 Design change record | D65: 项目小组 | E65: 俞锋 | F65: =WEEKNUM(G65) -> 0 | J65: =WEEKNUM(K65) -> 51 | K65: =M65 -> 45282 | L65: =WEEKNUM(M65) -> 51 | M65: =目录!H35 -> 45282
A67: 2.12 | B67: 工程规范确认表 Engineering specification confirmation form | D67: 技术部 | E67: 俞锋 | F67: =WEEKNUM(G67) -> 37 | G67: 2023/9/11 | H67: =WEEKNUM(I67) -> 37 | I67: =G67+1 -> 45181 | J67: =WEEKNUM(K67) -> 35 | K67: =M67 -> 45168 | L67: =WEEKNUM(M67) -> 35 | M67: =目录!H36 -> 45168
A69: 2.13 | B69: 材料规范确认表 Material specification confirmation form | D69: 技术部 | E69: 俞锋 | F69: =WEEKNUM(G69) -> 37 | G69: 2023/9/12 | H69: =WEEKNUM(I69) -> 37 | I69: =G69+1 -> 45182 | J69: =WEEKNUM(K69) -> 35 | K69: =M69 -> 45169 | L69: =WEEKNUM(M69) -> 35 | M69: =目录!H37 -> 45169
...

Sheet 0.05
F1: 密级：秘密★★，未经允许不可查看；保存期限：长期
A2: 设计评审/验证/确认记录 Design review/validation/validation records
J3: 序号NO.： | K3: 0.05
A4: 新产品名称 The name of the new product | C4: ='0.01'!C4:E5 -> 大块金用工业长丝-帘子布事业部PH25657 Nylon 66 tire cord fabric industrial yarn-Tire cord fabric Department PH25657 | G4: 新产品规格/型号Batch number and specification of new products | H4: ='0.01'!H4:K4 -> PH25657-2800dtex/432f
A5: 顾 客 名 称 The customer name | C5: ='0.01'!H5 -> 帘子布事业部 | G5: 日期 Date | H5: =目录!G10 -> 2023年8月16日
A6: 评审项目 Review project | C6: □设计开发输入 █产品设计输入 □ 可制造性 □ 产品设计输出 □ 过程设计输入 □ 过程设计输出 □安全投产输出 □ 量产输出
A8: 评审内容及记录Review contents and records | C8: 评审项目 | G8: 评审内容 | J8: 评审结论
C9: 产品性能要求 | E9: 详见《新产品开发申请立项报告》 | G9: 是否充分？ 是否适宜？ 要求是否完整？ 要求是否清楚？ 所有要求是否没有相矛盾？ | J9: □通过 □存在问题 □通过 □存在问题 □通过 □存在问题 □通过 □存在问题 □通过 □存在问题
C10: 可利用的类似产品信息 | E10: 涤纶高模低缩产品设计经验、尼龙工业长丝同类产品设计经验 | G10: 是否充分？ 是否适宜？ 要求是否完整？ 要求是否清楚？ 所有要求是否没有相矛盾？ | J10: □通过 □存在问题 □通过 □存在问题 □通过 □存在问题 □通过 □存在问题 □通过 □存在问题
C11: 适用于产品的法律、法规要求 | E11: 符合GB/T30512、ROHS、REACH | G11: 是否充分？ 是否适宜？ 要求是否完整？ 要求是否清楚？ 所有要求是否没有相矛盾？ | J11: □通过 □存在问题 □通过 □存在问题 □通过 □存在问题 □通过 □存在问题 □通过 □存在问题
C12: 适用于产品的标准和行业规范 | E12: 产品满足行标FZ∕T 54013锦纶66工业用长丝标准要求 | G12: 是否充分？ 是否适宜？ 要求是否完整？ 要求是否清楚？ 所有要求是否没有相矛盾？ | J12: □通过 □存在问题 □通过 □存在问题 □通过 □存在问题 □通过 □存在问题 □通过 □存在问题
C13: 由产品性质所导致的潜在失效后果的管控 | E13: 线密度在标准范围内尽可能保持稳定，降低线密度变异系数 | G13: 是否充分？ 是否适宜？ 要求是否完整？ 要求是否清楚？ 所有要求是否没有相矛盾？ | J13: □通过 □存在问题 □通过 □存在问题 □通过 □存在问题 □通过 □存在问题 □通过 □存在问题
E14: 断裂强度对成品帘子布的强力影响较大，生产过程中必须保证不低于标准强度
E15: 干热收缩率对帘子布的尺寸稳定性影响较大，生产过程中必须保证干热收缩率在标准范围内
E16: 其余性能指标按照现有的生产技术能力，可以满足客户的要求
A17: 评审结果 The results of the | C17: 设计开发输入完整、清楚，满足设计和开发的目的，评审通过。
A18: 评审人员会签 The judges will countersign
A19: 编制/日期Compilation/Date | G19: 审批/日期 Approval/Date
A20: 表单编号：HLD/CF-04-041-008 Form No：HLD/CF-04-041-008 | H20: 格式版次：第一版，第 2次修改 Format edition: first edition, 2 revision
D87: 评审结果前加客户反馈情况、交付满足情况、经验借鉴情况，可点链接

Sheet 0.05修改版
F1: 密级：秘密★★，未经允许不可查看；保存期限：长期
A2: 设计评审/验证/确认记录 Design review/validation/validation records
J3: 序号NO.： | K3: 0.05
A4: 新产品名称 The name of the new product | C4: ='0.01'!C4:E5 -> 大块金用工业长丝-帘子布事业部PH25657 Nylon 66 tire cord fabric industrial yarn-Tire cord fabric Department PH25657 | G4: 新产品规格/型号Batch number and specification of new products | H4: ='0.01'!H4:K4 -> PH25657-2800dtex/432f
A5: 顾 客 名 称 The customer name | C5: ='0.01'!H5 -> 帘子布事业部 | G5: 日期 Date | H5: =目录!G10 -> 2023年8月16日
A6: 评审阶段 | C6: □设计开发输入 █产品设计输入 □ 可制造性 □ 产品设计输出 □ 过程设计输入 □ 过程设计输出 □安全投产输出 □ 量产输出
A8: 评审内容及记录Review contents and records | C8: 评审项目 | G8: 评审内容 | J8: 评审结论
C9: 产品性能要求 | E9: 详见《新产品开发申请立项报告》 | G9: 是否充分？ 是否适宜？ 要求是否完整？ 要求是否清楚？ 所有要求是否没有相矛盾？ | J9: □通过 □存在问题 □通过 □存在问题 □通过 □存在问题 □通过 □存在问题 □通过 □存在问题
C10: 评审项目改成了评审阶段，点链接查看修改版 | E10: 涤纶高模低缩产品设计经验、尼龙工业长丝同类产品设计经验 | G10: 是否充分？ 是否适宜？ 要求是否完整？ 要求是否清楚？ 所有要求是否没有相矛盾？ | J10: □通过 □存在问题 □通过 □存在问题 □通过 □存在问题 □通过 □存在问题 □通过 □存在问题
C11: 适用于产品的法律、法规要求 | E11: 符合GB/T30512、ROHS、REACH | G11: 是否充分？ 是否适宜？ 要求是否完整？ 要求是否清楚？ 所有要求是否没有相矛盾？ | J11: □通过 □存在问题 □通过 □存在问题 □通过 □存在问题 □通过 □存在问题 □通过 □存在问题
C12: 适用于产品的标准和行业规范 | E12: 产品满足行标FZ∕T 54013锦纶66工业用长丝标准要求 | G12: 是否充分？ 是否适宜？ 要求是否完整？ 要求是否清楚？ 所有要求是否没有相矛盾？ | J12: □通过 □存在问题 □通过 □存在问题 □通过 □存在问题 □通过 □存在问题 □通过 □存在问题
C13: 由产品性质所导致的潜在失效后果的管控 | E13: 线密度在标准范围内尽可能保持稳定，降低线密度变异系数 | G13: 是否充分？ 是否适宜？ 要求是否完整？ 要求是否清楚？ 所有要求是否没有相矛盾？ | J13: □通过 □存在问题 □通过 □存在问题 □通过 □存在问题 □通过 □存在问题 □通过 □存在问题
E14: 断裂强度对成品帘子布的强力影响较大，生产过程中必须保证不低于标准强度
E15: 干热收缩率对帘子布的尺寸稳定性影响较大，生产过程中必须保证干热收缩率在标准范围内
E16: 其余性能指标按照现有的生产技术能力，可以满足客户的要求
A17: 评审结果 The results of the | C17: 设计开发输入完整、清楚，满足设计和开发的目的，评审通过。
A18: 评审人员会签 The judges will countersign
A19: 编制/日期Compilation/Date | G19: 审批/日期 Approval/Date
A20: 表单编号：HLD/CF-04-041-008 Form No：HLD/CF-04-041-008 | H20: 格式版次：第一版，第 2次修改 Format edition: first edition, 2 revision
D87: 评审结果前加客户反馈情况、交付满足情况、经验借鉴情况，可点链接

Sheet 1.01
E1: 密级：秘密★★，未经允许不可查看；保存期限：长期
A2: 设计开发任务书 Design and development specification
I3: 序号NO.： | J3: 1.01
A4: 新产品名称 The name of the new product | C4: ='0.01'!C4:E5 -> 大块金用工业长丝-帘子布事业部PH25657 Nylon 66 tire cord fabric industrial yarn-Tire cord fabric Department PH25657 | F4: 新产品批号和规格Batch number and specification of new products | H4: ='0.01'!H4:K4 -> PH25657-2800dtex/432f
A5: 顾客名称 The customer name | C5: ='0.01'!H5 -> 帘子布事业部 | F5: 日期 Date | H5: =目录!G12 -> 2023年8月17日
A6: 一、依据的标准、法律法规及技术协议的主要内容：Standards, laws and regulations and main contents of the technical agreement: 1、以海利得尼龙工业长丝企业标准和尼龙工业长丝外观定等标准为基础。 2、设计要求符合IATF16949质量管理体系标准和ISO14001:2015环境管理体系标准。 3、与传统工业丝一样，没有添加任何新化学原料，符合化学品管理条例。
A7: 二、设计内容：Design content : 1、原料切片粘度的选择---神马尼龙切片，粘度IV：3.**±0.10 2、纺丝生产机型的选择----尼龙生产线
A8: 三、设计目标（包括过程能力、生产率、成本等）：Design objectives (including process capability, productivity, cost, etc.)
A9: 项目目标 project objective | C9: 指标 target | F9: 责任人 person liable | G9: 责任人 | H9: 统计时间 statistical time
A10: 1.日程安排 | C10: 2023年8月完成试样 | F10: APQP团队 | G10: APQP团队 | H10: 第二阶段结束
A11: 2.过程能力 | C11: CC/SC项PPK≥1.67或CPK≥1.67 （当数据符合正态分布且稳定时看CPK，当数据不符合正态分布或不稳定时看PPK） | F11: APQP团队 | G11: APQP团队 | H11: 第二阶段、第四阶段结束
A12: 3.开发成本 | C12: 成本控制与其他尼龙66工业长丝产品类似 | F12: APQP团队 | G12: APQP团队 | H12: 第四阶段结束
A13: 4.生产率 | C13: ≥0.9吨/天/位 | F13: APQP团队 | G13: APQP团队 | H13: 第四阶段结束
A14: 5.产品符合性（CC/SC项，其余一般特性见《立项报告》）： | C14: ='0.02'!B11 -> 线密度 Linear Density | D14: ='0.02'!G11 -> 2880±30 | E14: ='0.02'!E11:F11 -> dtex | F14: APQP团队 | G14: APQP团队 | H14: 第二阶段、第四阶段结束
C15: ='0.02'!B13 -> 断裂强力 Breaking Strength | D15: ='0.02'!G13 -> ≥245.0 | E15: ='0.02'!E13:F13 -> N | F15: APQP团队 | G15: APQP团队 | H15: 第二阶段、第四阶段结束
C16: ='0.02'!B16 -> 断裂伸长率 Breaking Elongation Ratio | D16: ='0.02'!G16 -> 20.0±3.0 | E16: ='0.02'!E16:F16 -> % | F16: APQP团队 | G16: APQP团队 | H16: 第二阶段、第四阶段结束
C17: ='0.02'!B19 -> 干热收缩率（177℃×2min×0.05cN/dtex) Shrinkage in Hot Air | D17: ='0.02'!G19 -> 6.2±1.5 | E17: ='0.02'!E19 -> % | F17: APQP团队 | G17: APQP团队 | H17: 第二阶段、第四阶段结束
A18: 6.可靠性及质量目标 | C18: 优等率≥90% | F18: APQP团队 | G18: APQP团队 | H18: 第四阶段结束
A19: 7.APQP指标 | C19: 见项目计划 | F19: APQP团队 | G19: APQP团队 | H19: 每个阶段结束时
A20: 顾客的特殊要求： □有 □无
A21: 详细要求：客户其他要求均能满足要求，详见客户要求清单。
A22: 项目团队会签 Team members will countersign
A23: 编制/日期 Compilation/Date | F23: 审批/日期Approval/Date
A24: 表单编号：HLD/CF-04-041-009 Form No : HLD/CF-04-041-009 | G24: 格式版次：第一版，第2次修改 Format edition: first edition, 2 revision

Sheet 1.02
D1: 密级：秘密★★，未经允许不可查看；保存期限：长期
A2: 初始材料清单（BOM） Initial material list (BOM)
H3: 序号NO.： | I3: 1.02
A4: 新产品名称 The name of the new product | C4: ='0.01'!C4:E5 -> 大块金用工业长丝-帘子布事业部PH25657 Nylon 66 tire cord fabric industrial yarn-Tire cord fabric Department PH25657 | F4: 顾客名称 The customer name | G4: ='0.01'!H5 -> 帘子布事业部
A5: 新产品规格/型号 Batch number and specification of new products | C5: ='0.01'!H4 -> PH25657-2800dtex/432f | F5: 制定日期 Set the date | G5: =目录!G13 -> 2023年8月18日
A6: 制定部门 Develop department | C6: 技术部 | F6: 修订日期 The revision date | G6: =目录!G70 -> 2025年5月6日
A7: 序号STT | B7: 材料名称 The name of the material | D7: 规格/型号Specification/Model | E7: 供应商名称 Supplier name | F7: 是否已准入 Whether it has been approved | G7: 准入计划 Admission Plan | I7: 实际完成时间 actual finish time
A8: 1 | B8: 尼龙66切片 | D8: FYR32KD | E8: 021156 | F8: √ | G8: / | H8: / | I8: /
A9: 2 | B9: 纺丝油剂 | D9: SLT-B-100E | E9: 02821 | F9: √
A10: 3 | B10: 纸管 | D10: 94*106*300mm | E10: 恒旺 | F10: √ | G10: / | H10: / | I10: /
A11: 4 | B11: 木托盘 | D11: 110*110CM（墩子） | E11: 宏旺 | F11: √
A12: 5 | B12: 塑料袋 | D12: 54*72mm黑色 | E12: 正欣 | F12: √ | G12: / | H12: / | I12: /
A13: 6 | B13: 护角 | D13: 8cm | E13: 好运 | F13: √
A14: 7 | B14: 缠绕膜 | D14: 500*0.025 | E14: 鸿鹰 | F14: √ | G14: / | H14: / | I14: /
A15: 8 | B15: PP打包带 | D15: 12*0.9,10kg | E15: 天恩 | F15: √
A16: 9 | B16: 蜂窝板 | D16: 1120*1120*50mm 1120*1120*25mm | E16: 永基 | F16: √ | G16: / | H16: / | I16: /
A17: 10 | B17: 纸箱 | D17: 3A/112*112圆角下盖 | E17: 先锋 | F17: √
A18: 备 注
A19: 编制/日期Compilation/Date | F19: 审批/日期Approval/Date
A21: 表单编号：HLD/CF-04-041-011 Form No : HLD/CF-04-041-011 | F21: 格式版次：第一版，第1次修改 Format edition: first edition, 1 revision

Sheet 1.03
E1: 密级：秘密★★，未经允许不可查看；保存期限：长期
A2: 成本核算及报价表 Cost accounting and quotation sheet
M3: 序号NO.： | N3: 1.03
A4: 新产品名称 The name of the new product | D4: ='0.01'!C4 -> 大块金用工业长丝-帘子布事业部PH25657 Nylon 66 tire cord fabric industrial yarn-Tire cord fabric Department PH25657 | H4: 新产品规格/型号 Batch number and specification of new products | L4: ='0.01'!H4 -> PH25657-2800dtex/432f
A5: 顾 客 名 称 The customer name | D5: ='0.01'!H5 -> 帘子布事业部 | H5: 日期 Date | L5: =目录!G14 -> 2023年8月18日
A6: 资金来源 Source of funds | E6: 拨 款 grant | G6: 贷 款 The loans | I6: 自 筹 Since the raise | L6: 其 它 other | M6: 合 计 total
A7: 经费（万元）
A8: 经费明细表 A breakdown of expenses 单位： 元
A9: 序号STT | B9: 项 目 分 类 Project classification | H9: 核算费用Cost accounting | J9: （工作量） | L9: （核算标准） | N9: 小 计subtotal
A10: 1 | B10: 直 接direct | C10: 聚酯切片 | H10: 7500 | N10: =SUM(H10:I12) -> 8650
B11: 材料费material fee | C11: 油剂 | H11: 600
C12: 包装材料 | H12: 550
A13: 2 | B13: 化验分析费Laboratory analysis fee | C13: 切片IV测试 | H13: 150 | N13: =SUM(H13:I17) -> 350
C14: 含油丝IV测试 | H14: 150
C15: 含油率测试 | H15: 50
A18: 3 | B18: 燃料动力消耗费 Fuel power consumption fee | H18: 800 | N18: =SUM(H18) -> 800
A19: 4 | B19: 设备购置费（设备名称及型号）Equipment purchase fee (equipment name and model) | H19: 0 | N19: 0
A20: 5 | B20: 小型样机试制费（样机名称）Small prototype trial production fee (name of prototype) | H20: 0 | N20: 0
A21: 6 | B21: 现场试验费 Field test fee | H21: 0 | N21: 0
A22: 7 | B22: 其 他Other | C22: 外协费 Outsourcing fee | H22: 0 | N22: =SUM(H22:I26,H27) -> 3500
C23: 调研费 Research fee | H23: 0
C24: 培训费 training fee | H24: 0
C25: 会议评审费 Conference review fee | H25: 0
C26: 运输费 Shipping fee | H26: 3500
A27: 8 | B27: 不可预见费 Unforeseen expenses | H27: 0
A28: 9 | B28: 设备、房屋Equipment, housing | D28: （设备名称）Device name | H28: 0 | N28: 0
B29: 占用费Occupancy fee | D29: （房屋用途）Housing purposes | H29: 0
A30: 10 | B30: 直接人员费用（按全工时人数）Direct staff costs (based on the number of people working in full hours) | H30: 600
A31: 总 计 Total | H31: 1*900元/吨
A32: 编制/日期 Compilation/Date | H32: 审批/日期Approval/Date
A33: 表单编号：HLD/CF-04-041-004 Form No：HLD/CF-04-041-004 | K33: 格式版次：第一版，第1次修改 Format edition: first edition, 1 revision

Sheet 1.03修改版
E1: 密级：秘密★★，未经允许不可查看；保存期限：长期
A2: 成本核算及报价表 Cost accounting and quotation sheet
M3: 序号NO.： | N3: 1.03
A4: 新产品名称 The name of the new product | D4: ='0.01'!C4 -> 大块金用工业长丝-帘子布事业部PH25657 Nylon 66 tire cord fabric industrial yarn-Tire cord fabric Department PH25657 | H4: 新产品规格/型号 Batch number and specification of new products | L4: ='0.01'!H4 -> PH25657-2800dtex/432f
A5: 顾 客 名 称 The customer name | D5: ='0.01'!H5 -> 帘子布事业部 | H5: 日期 Date | L5: =目录!G14 -> 2023年8月18日
A6: 资金来源 Source of funds | E6: 拨 款 grant | G6: 贷 款 The loans | I6: 自 筹 Since the raise | L6: 其 它 other | M6: 合 计 total
A7: 经费（万元）
A8: 经费明细表 A breakdown of expenses 单位： 元
A9: 序号STT | B9: 项 目 分 类 Project classification | H9: 核算费用Cost accounting | J9: （工作量） | L9: （核算标准） | N9: 小 计subtotal
A10: 1 | B10: 直 接direct | C10: 聚酯切片 | H10: 7500 | N10: =SUM(H10:I12) -> 8650
B11: 材料费material fee | C11: 油剂 | H11: 600
C12: 包装材料 | H12: 550
A13: 2 | B13: 化验分析费Laboratory analysis fee | C13: 切片IV测试 | H13: 150 | N13: =SUM(H13:I17) -> 350
C14: 含油丝IV测试 | H14: 150
C15: 含油率测试 | H15: 50
A18: 3 | B18: 燃料动力消耗费 Fuel power consumption fee | H18: 800 | N18: =SUM(H18) -> 800
B19: 能耗费用（水电） | O19: 发给体系老师看下
A20: 4 | B20: 设备购置费（设备名称及型号）Equipment purchase fee (equipment name and model) | H20: 0 | N20: 0
A21: 5 | B21: 小型样机试制费（样机名称）Small prototype trial production fee (name of prototype) | H21: 0 | N21: 0
A22: 6 | B22: 现场试验费 Field test fee | H22: 0 | N22: 0
A23: 7 | B23: 其 他Other | C23: 外协费 Outsourcing fee | H23: 0 | N23: =SUM(H23:I27,H28) -> 3500
C24: 调研费 Research fee | H24: 0
C25: 培训费 training fee | H25: 0
C26: 会议评审费 Conference review fee | H26: 0
C27: 运输费 Shipping fee | H27: 3500
A28: 8 | B28: 不可预见费 Unforeseen expenses | H28: 0
A29: 9 | B29: 设备、房屋Equipment, housing | D29: （设备名称）Device name | H29: 0 | N29: 0
B30: 占用费Occupancy fee | D30: （房屋用途）Housing purposes | H30: 0
A31: 10 | B31: 直接人员费用（按全工时人数）Direct staff costs (based on the number of people working in full hours) | H31: 600
A32: 总 计 Total | H32: 1*900元/吨
A33: 编制/日期 Compilation/Date | H33: 审批/日期Approval/Date
A34: 表单编号：HLD/CF-04-041-004 Form No：HLD/CF-04-041-004 | K34: 格式版次：第一版，第1次修改 Format edition: first edition, 1 revision

Sheet 1.04
E1: 密级：秘密★★，未经允许不可查看；保存期限：长期
A2: 过程流程图（初始） Process flow Chart (initial)
M3: 序号NO.：1.04
A4: 新产品名称 The name of the new product | C4: ='0.01'!C4:E5 -> 大块金用工业长丝-帘子布事业部PH25657 Nylon 66 tire cord fabric industrial yarn-Tire cord fabric Department PH25657 | H4: 新产品批号和规格 Batch number and specification of new products | I4: ='0.01'!H4 -> PH25657-2800dtex/432f | J4: 顾 客 名 称 The customer name | L4: ='0.01'!H5 -> 帘子布事业部
A6: 编制 Preparde by | C6: 于淼 Yu Miao | H6: 批准 Appoved by | I6: 顾锋 Gu Feng | J6: 日期(初稿) Date(First Draft) | L6: =目录!G15 -> 2023年8月19日
A7: 生产线 production line | C7: F、H | G7: 产品类别：尼龙66工业长丝 Part Category：Nylon 66 industrial yarn
A8: 工位名称 Process Name | B8: 步骤 Step | C8: 制造 manufacture | D8: 移动 Moving | E8: 放置 Placing | F8: 检查 Checking | G8: 操作说明 Illumination of Operation | J8: 产品特殊特性 Key Product Characteristics | L8: 过程特殊特性 Key Control Characteristics
J9: 项目Projects | K9: 级别Levels | L9: 项目Projects | M9: 级别levels
A10: 投料 Feeding | B10: PA661100 | G10: 将从仓库领取的尼龙66切片投料至大料仓 Feed the nylon 66 chips collected from the warehouse into the large silo
A11: 切片输送 PET chip transport | B11: PA661200 | G11: 使用氮气将尼龙66切片从大料仓输送至纺丝料仓 The nylon 66 chips are conveyed from the buffer silo to the spinning silo using nitrogen
A12: 切片存储 Storage of Nylon 66 chips | B12: PA661300 | G12: 尼龙66切片在纺丝料仓中存储 Nylon 66 chips are stored in the chip spinning silo
A13: 螺杆熔融 Melton by screw | B13: PA661400 | G13: 纺丝料斗中的高粘度切片，在重力作用下进入螺杆熔融挤出 The viscosified chips will be fed into the scew for melting.
A14: 熔体计量 Melt metering | B14: PA661500 | G14: 螺杆挤出后的熔体经过熔体分配管通过计量泵精确计量 The melt of polymer extruded by srew, then be measured and transported by the metering pump | J14: 线密度 Linear density | K14: SC | L14: 计量泵转速 Rotating speed of Metering pump | M14: SC
A15: 喷丝 spinning | B15: PA661600 | G15: 计量后的熔体通过组件喷出丝束 The measured melt will be extruded into the spinining pack and form into the fresh born yarn.
A16: 冷却成型 cooling and molding | B16: PA661700 | G16: 熔体丝束通过加热罩、缓冷装置和冷却风，固化成初生丝束 The yarn go through the heating hood and quenching air to modify the initial properties of new born yarn. | J16: 断裂伸长 Breaking elongation ratio | K16: CC | L16: 加热罩温度 Heating hood temperature 侧吹风温度 Lateral air temperature | M16: CC
A17: 上油 Adding oil | B17: PA661800 | G17: 通过上油轮将纺丝油剂吸附至丝束表面上 Apply the spin finish onto the surface of yarn by kiss roller.
A18: 拉伸定型 stretching and sizing | B18: PA661900 | G18: 上油后的丝束经罗拉多级拉伸和热定型，以达到设计物性性能 The oiled yarn will be stretched and sized by serveral pairs of roller, to make the yarn get the certain physical properties. | J18: 断裂强力 Breaking strength | K18: CC | L18: 罗拉速度 Speed of roller | M18: CC
J19: 干热收缩率 Shrinkage in Hot Air | K19: SC | L19: 罗拉温度 Temperature of roller | M19: SC
A20: 上网络 Adding intermingle | B20: PA662000 | G20: 拉伸和定型后的丝束，经网络器和压空的作用获得网络节点 The streched and sized yarn will be insert into the air-jet device for making the entanglement.
A21: 毛丝检测 Detection of the broken filament | B21: PA662100 | G21: 丝束经过毛丝检测仪在线记录毛丝个数 Use the online broken filament detector to examine the quantity of broken filament of the bobbin.
A22: 卷绕 Winding | B22: PA662200 | G22: 用规定颜色的纸管将丝束通过卷绕机卷绕成一定卷重的丝筒 The winder will take up yarn onto the paper core which has specific color requirement.
A23: 落丝 Doffing | B23: PA662300 | G23: 把卷绕完成的丝筒根据不同毛丝等级按规定摆放到相应丝车上，并贴好小标签Separate the finished bobbins according to the criterion of broken filament, label the bobbin according accordingly, then load the bobbins onto the different trolley respectively.
A24: 剥丝 Stripping | B24: PA662400 | G24: 抽吸丝饼表层丝，剥丝完成后打结 Peel off the surface yarn which may has quality risk, and tie a knot.
A25: 检验 Inspection | B25: PA662500 | G25: 对丝筒物性抽检，外观全检，并根据检验结果定等 Make the physical properties inspection and apperance inspection for the finished bobbins, then grading these finished bobbins according to the specific quality criterion. | J25: 线密度 Linear density | K25: SC
J26: 断裂伸长 Breaking elongation ratio | K26: CC
J27: 断裂强力 Breaking strength | K27: CC
J28: 干热收缩率 Shrinkage in Hot Air | K28: SC
A29: 包装 Packing | B29: PA662600 | G29: 根据生产通知单和包装标准进行丝饼二维码扫描、丝饼装箱打包并称重Scan QR code of bobbin and pack up the bobbin according to the packing standard and produciton order, then weight them.
A30: 入库 Warehousing | B30: PA662700 | G30: 将包装好的产品用叉车运送至仓库指定区域 Transport the packaged goods to the designated area of the warehouse.
A31: 交付 Deliver | B31: PA662800 | G31: 根据销售订单对已入库产品进行装车交付 According to the sales order, load and deliver the warehousing products
A32: 注：CC代表关键特性，SC代表重要特性。 Noted:CC represent critcal characters,SC represent significant characters.

Sheet 1.05
E1: 密级：秘密★★，未经允许不可查看；保存期限：长期
A2: 特殊特性符号转化表 Special properties symbol conversion table
F3: 序号NO.：1.05
A4: 新产品名称 The name of the new product | C4: ='0.01'!C4 -> 大块金用工业长丝-帘子布事业部PH25657 Nylon 66 tire cord fabric industrial yarn-Tire cord fabric Department PH25657 | F4: 日期 Date | H4: =目录!G16 -> 2023年8月20日
B5: 顾客名称The customer name | C5: ='0.01'!H5 -> 帘子布事业部 | F5: HALEAD （内部）
A6: 特殊特性Special features | F6: 定义 | H6: 符号
A7: 安全/法规Safety/Regulations | C7: —— | F7: S≥9 | H7: CC
A8: 关键特性 The key features | C8: ★ | F8: S≥9 | H8: CC
A9: 重要特性 Important features | C9: ◇ | F9: 5≤S≤8且O≥5 | H9: SC
A10: 一般特性 General features | C10: —— | F10: —— | H10: ——
A12: 备注：根据顾客要求、类似经验等，确定产品的特殊特性，包括关键特性、重要特性、一般特性。
A13: 编制/日期Compilation/Date | E13: 审批/日期 Approval/Date
A14: 表单编号：HLD/CF-04-041-025 Form No. : HLD/CF-04-041-025 | F14: 格式版次：第一版，第2次修改 Format edition: first edition, 2 revision

Sheet 1.06
E1: 密级：秘密★★，未经允许不可查看；保存期限：长期
A2: 产品/过程特殊特性清单 List of product/process special features
F4: 序号NO.：1.06
A5: 新产品名称 The name of the new product | C5: ='0.01'!C4 -> 大块金用工业长丝-帘子布事业部PH25657 Nylon 66 tire cord fabric industrial yarn-Tire cord fabric Department PH25657 | E5: 新产品规格/型号 Batch number and specification of new products | G5: ='0.01'!H4 -> PH25657-2800dtex/432f
A6: 顾 客 名 称 The customer name | C6: ='0.01'!H5 -> 帘子布事业部 | E6: 日期 Date | G6: =目录!G17 -> 2023年8月20日
A7: 序号 STT | B7: 产品特性 Key Produc Characteristic | D7: 过程特性 Key Control Characteristic | F7: 控制手段 Control method | G7: 责任部门 The responsibility department | H7: 备注
B8: 描述Describe | C8: 符号Symbol | D8: 描述Describe | E8: 符号Symbol
A9: 1 | B9: 线密度 Linear density | C9: SC | F9: SPC管控图 | G9: 化纤事业部
A10: 2 | B10: 断裂强力 Tenacity at break | C10: CC | F10: SPC管控图 | G10: 化纤事业部
A11: 3 | B11: 断裂伸长 Elongation at break | C11: CC | F11: SPC管控图 | G11: 化纤事业部
A12: 4 | B12: 干热收缩率 Shinkage in hot air | C12: SC | F12: SPC管控图 | G12: 化纤事业部
A13: 5 | D13: 计量泵转速 speed of metering pump | E13: SC | F13: 100%实时监控 | G13: 化纤事业部
A14: 6 | D14: 加热罩温度 Heating hood temperature | E14: CC | F14: 100%实时监控 | G14: 化纤事业部
A15: 7 | D15: 侧吹风温度 Quenching air temperature | E15: CC | F15: 100%实时监控 | G15: 化纤事业部
A16: 8 | D16: 罗拉温度 temperature of roller | E16: SC | F16: 100%实时监控 | G16: 化纤事业部
A17: 9 | D17: 罗拉速度 speed of roller | E17: CC | F17: 100%实时监控 | G17: 化纤事业部
A18: 备注：CC表示关键特性,SC表示重要特性。
A19: 编制/日期Compilation/Date | E19: 审批/日期Approval/Date
A20: 表单编号：HLD/CF-04-041-012 Form No ：HLD/CF-04-041-012 | F20: 格式版次：第一版，第1次修改 Format edition: first edition, 1 revision

Sheet 1.07
E1: 密级：秘密★★，未经允许不可查看；保存期限：长期
A2: 产品安全识别表 Product safety identification form
A3: 序号NO.：1.07
A4: 新产品名称 The name of the new product | C4: ='0.01'!C4 -> 大块金用工业长丝-帘子布事业部PH25657 Nylon 66 tire cord fabric industrial yarn-Tire cord fabric Department PH25657 | F4: 新产品批号和规格Batch number and specification of new products | H4: ='0.01'!H4 -> PH25657-2800dtex/432f
A5: 顾 客 名 称 The customer name | C5: ='0.01'!H5 -> 帘子布事业部 | F5: 日期 Date | H5: =目录!G18 -> 2023年8月21日
A6: 项目 project | C6: 产品安全要求 Product safety requirements | F6: 风险评估 risk assessment | G6: 责任人 | H6: 控制方法 control method
A7: 1 | B7: 产品安全方面的相关法规 | C7: 该产品不涉及安全方面的法规 | F7: NA | H7: NA
A8: 2 | B8: 安全相关特殊特性 | C8: ='1.01'!C15 -> 断裂强力 Breaking Strength | D8: ='1.01'!D15 -> ≥245.0 | E8: ='1.01'!E15 -> N | F8: 在DFMEA及PFMEA中分析 | H8: 1、在控制计划中规定控制方法及反应计划 2、在FMEA、控制计划、作业指导书等文件中标识符合
A9: 3 | B9: 安全相关特殊特性 | C9: ='1.01'!C16 -> 断裂伸长率 Breaking Elongation Ratio | D9: ='1.01'!D16 -> 20.0±3.0 | E9: ='1.01'!E16 -> % | F9: 在DFMEA及PFMEA中分析 | H9: 1、在控制计划中规定控制方法及反应计划 2、在FMEA、控制计划、作业指导书等文件中标识符合
A10: 4
A11: 5
A12: 6
A13: 7
A14: 编制/日期 Compilation/Date | F14: 审批/日期 Approval/Date
A15: 表单编号：HLD/CF-04-041-047 Form No：HLD/CF-04-041-047 | H15: 格式版次：第一版，第0次修改 Format edition: first edition, 0 revision

Sheet 1.07修改版
E1: 密级：秘密★★，未经允许不可查看；保存期限：长期
A2: 产品安全识别表 Product safety identification form
A3: 序号NO.：1.07
A4: 新产品名称 The name of the new product | C4: ='0.01'!C4 -> 大块金用工业长丝-帘子布事业部PH25657 Nylon 66 tire cord fabric industrial yarn-Tire cord fabric Department PH25657 | F4: 新产品批号和规格Batch number and specification of new products | H4: ='0.01'!H4 -> PH25657-2800dtex/432f
A5: 顾 客 名 称 The customer name | C5: ='0.01'!H5 -> 帘子布事业部 | F5: 日期 Date | H5: =目录!G18 -> 2023年8月21日
A6: 项目 project | C6: 产品安全要求 Product safety requirements | F6: 风险评估 risk assessment | G6: 责任人 | H6: 控制方法 control method
A7: 1 | B7: 产品安全方面的相关法规 | C7: 该产品不涉及安全方面的法规 | F7: NA | H7: NA
A8: 2 | B8: 安全相关特殊特性 | C8: ='1.01'!C15 -> 断裂强力 Breaking Strength | D8: ='1.01'!D15 -> ≥245.0 | E8: ='1.01'!E15 -> N | F8: 在DFMEA及PFMEA中分析 | H8: 1、在控制计划中规定控制方法及反应计划 2、在FMEA、控制计划、作业指导书等文件中标识符合
A9: 3 | B9: 安全相关特殊特性 | C9: ='1.01'!C16 -> 断裂伸长率 Breaking Elongation Ratio | D9: ='1.01'!D16 -> 20.0±3.0 | E9: ='1.01'!E16 -> % | F9: 在DFMEA及PFMEA中分析 | H9: 1、在控制计划中规定控制方法及反应计划 2、在FMEA、控制计划、作业指导书等文件中标识符合
A10: 4 | B10: 有害物质 | C10: 满足要求
A11: 5
A12: 6
A13: 7
A14: 编制/日期 Compilation/Date | F14: 审批/日期 Approval/Date
A15: 表单编号：HLD/CF-04-041-047 Form No：HLD/CF-04-041-047 | H15: 格式版次：第一版，第0次修改 Format edition: first edition, 0 revision

Sheet 1.08
E1: 密级：秘密★★，未经允许不可查看；保存期限：长期
A2: 产品保证计划 Product Assurance Program
A3: 序号NO.：1.08
A4: 新产品名称 The name of the new product | C4: ='0.01'!C4 -> 大块金用工业长丝-帘子布事业部PH25657 Nylon 66 tire cord fabric industrial yarn-Tire cord fabric Department PH25657 | F4: 新产品批号和规格Batch number and specification of new products | H4: ='0.01'!H4 -> PH25657-2800dtex/432f
F5: 顾 客 名 称 The customer name | H5: ='0.01'!H5 -> 帘子布事业部
A6: 制定部门 Designated department | C6: 技术部 | F6: 制定日期 Fixed date | H6: =目录!G19 -> 2023年8月21日
A7: 一、项目要求概述（简要的说明新产品项目开发的各项要求 Brief description of the requirements of the new product project development
A8: 顾客对新产品开发项目的质量和技术要求及其它基本要求： Customer's quality and technical requirements and other basic requirements for new product development projects:
A9: 顾客对新产品开发项目的质量和技术要求及其它基本要求：规格为2800dtex/432f ，断裂强度≥8.50cN/dtex.
A10: 二、产品可靠性，耐久性和分配目标的要求Requirements for product reliability, durability and distribution targets
A11: 见产品规范
A13: 三、风险分析/评估：Risk Analysis/Assessment:
A14: 序号 STT | B14: 项 目 Item | C14: 可能带来的风险 Possible risks | F14: 解 决 方 法 Solution | J14: 备 注 Remarks
A15: 1 | B15: 新技术 | C15: 无 | F15: 无
A16: 2 | B16: 毛丝 | C16: 毛丝多会造成布外观毛 | F16: 总结以往类似尼龙工业长丝毛丝控制的经验
A17: 3 | B17: 包 装 | C17: 打包不规范.包装不牢固，运输过程中造成破损 | F17: 员工培训
A18: 4 | B18: 服 务 | C18: 产品投诉 | F18: 及时接受和持续做分析.纠正预防
A19: 5 | B19: 制 造 | C19: 生产过程出现工作失误 | F19: 作业指导书和生产控制计划
A20: 6 | B20: 其 它 | C20: 无 | F20: 无
